Workbook

Sheet 00_ReadMe
A1: Realcorp Unit Economics | B1: SaaS + Shortlets + WhatsApp booking take-rate model
A2: Currency | B2: All figures in Nigerian Naira (₦) unless noted
A3: How to use | B3: 1) Edit yellow/orange INPUT cells on Assumptions. 2) Review Plan_Economics, Shortlets, LTV. 3) Change Scenario_Mix for portfolio view.
A4: Do not edit | B4: Blue/formula columns — they recalculate from Assumptions
A5: Pricing thesis | B5: Base SaaS (org) + seats + per shortlet LOCATION + % take-rate only when Realcorp/WhatsApp books or collects payment
A6: Plans | B6: STARTER / GROWTH / ENTERPRISE (matches TenantPlan in product)
A7: Shortlets meter | B7: Bill ShortletProperty (location), not every unit/room
A8: Offline cash | B8: 0% take-rate by default — do not tax walk-in cash outside your rails
A9: Version | B9: 2026-09-07

Sheet 01_Assumptions
A1: ASSUMPTIONS — edit yellow cells
A3: A. Platform & delivery cost (monthly, allocated)
A4: Infra (Netlify/DB/CDN) | B4: 120000 | C4: Hosting, Postgres, CDN, email
A5: AI base (Gemini budget) | B5: 40000 | C5: Before metered overage
A6: Support / CS allocation | B6: 350000 | C6: Partial FTE + WhatsApp support
A7: Payment tools fixed | B7: 15000 | C7: Paystack dashboard etc.
A8: Other SaaS tools | B8: 50000 | C8: Sentry, analytics, design
A9: Total fixed monthly OpEx (platform) | B9: =B4+B5+B6+B7+B8
A11: B. Variable cost per active org / month
A12: COGS_per_org_base | B12: 8000 | C12: DB/storage/support load per tenant
A13: COGS_per_extra_seat | B13: 500 | C13: Marginal cost per seat
A14: COGS_per_shortlet_location | B14: 2500 | C14: Hosting/ops per active location
A15: COGS_AI_per_doc_extract | B15: 80 | C15: Gemini cost per successful extract
A16: Paystack_percent | B16: 0.015 | C16: Payment processor % (illustrative)
A17: Paystack_flat | B17: 100 | C17: Flat fee per txn if any
A19: C. SaaS list prices (monthly)
A20: Starter_price | B20: 90000 | C20: 5 seats included
A21: Growth_price | B21: 225000 | C21: 15 seats — recommended default
A22: Enterprise_price | B22: 500000 | C22: 40 seats
A23: Extra_seat_Starter | B23: 8000
A24: Extra_seat_Growth | B24: 7000
A25: Extra_seat_Enterprise | B25: 5000
A26: Seats_incl_Starter | B26: 5
A27: Seats_incl_Growth | B27: 15
A28: Seats_incl_Enterprise | B28: 40
A30: D. Shortlets pricing
A31: Shortlets_addon_monthly | B31: 70000 | C31: Module access; includes N locations
A32: Locations_included | B32: 2 | C32: In shortlets add-on
A33: Extra_location_monthly | B33: 20000 | C33: Per ShortletProperty beyond included
A34: Take_rate_checkout | B34: 0.03 | C34: % when paid via Realcorp checkout
A35: Take_rate_whatsapp | B35: 0.04 | C35: % when booked via WhatsApp agent then paid
A36: Take_rate_offline | B36: 0 | C36: % walk-in cash outside rails
A37: Pass_through_paystack | B37: 1 | C37: 1=subtract processor from your take, 0=customer pays processor
A39: E. Sales & retention assumptions
A40: CAC_blended | B40: 180000 | C40: Sales+ads+founder time per won logo
A41: Setup_fee_avg | B41: 250000 | C41: One-time implementation (avg)
A42: Setup_delivery_cost | B42: 80000 | C42: Your cost to onboard (hours)
A43: Gross_margin_target | B43: 0.75 | C43: Target contribution margin
A44: Monthly_churn_Starter | B44: 0.05 | C44: 5% MoM
A45: Monthly_churn_Growth | B45: 0.03
...

Sheet 02_Plan_Economics
A1: Monthly unit economics by plan (typical seat counts)
A3: Metric | B3: Starter | C3: Growth | D3: Enterprise | E3: Notes
A4: List price (base) | B4: =01_Assumptions!B20 | C4: =01_Assumptions!B21 | D4: =01_Assumptions!B22 | E4: Monthly SaaS
A5: Seats used (typical) | B5: =01_Assumptions!B51 | C5: =01_Assumptions!B52 | D5: =01_Assumptions!B53
A6: Seats included | B6: =01_Assumptions!B26 | C6: =01_Assumptions!B27 | D6: =01_Assumptions!B28
A7: Extra seats | B7: =MAX(0,B5-B6) | C7: =MAX(0,C5-C6) | D7: =MAX(0,D5-D6)
A8: Extra seat revenue | B8: =B7*01_Assumptions!B23 | C8: =C7*01_Assumptions!B24 | D8: =D7*01_Assumptions!B25
A9: SaaS revenue (mo) | B9: =B4+B8 | C9: =C4+C8 | D9: =D4+D8 | E9: Before shortlets
A10: Collected SaaS (mo) | B10: =B9*01_Assumptions!B48 | C10: =C9*01_Assumptions!B48 | D10: =D9*01_Assumptions!B48 | E10: After collection rate
A11: COGS: base org | B11: =01_Assumptions!B12 | C11: =01_Assumptions!B12 | D11: =01_Assumptions!B12
A12: COGS: seats | B12: =B5*01_Assumptions!B13 | C12: =C5*01_Assumptions!B13 | D12: =D5*01_Assumptions!B13
A13: COGS: AI (Growth+) | B13: 0 | C13: =01_Assumptions!B59*01_Assumptions!B15 | D13: =01_Assumptions!B59*01_Assumptions!B15*1.5 | E13: Enterprise uses more AI
A14: Total variable COGS | B14: =B11+B12+B13 | C14: =C11+C12+C13 | D14: =D11+D12+D13
A15: Contribution (₦) | B15: =B10-B14 | C15: =C10-C14 | D15: =D10-D14 | E15: Before fixed OpEx allocation
A16: Contribution margin % | B16: =IF(B10=0,0,B15/B10) | C16: =IF(C10=0,0,C15/C10) | D16: =IF(D10=0,0,D15/D10) | E16: Target ~75%
A17: vs margin target | B17: =B16-01_Assumptions!B43 | C17: =C16-01_Assumptions!B43 | D17: =D16-01_Assumptions!B43 | E17: Positive = beating target
A20: Interpretation
A21: Growth should be your volume plan: high contribution, seats under included limit, HR/AI attached. Starter is acquisition; Enterprise is margin + expansion.

Sheet 03_Shortlets
A1: Shortlets: location fee + take-rate unit economics
A3: Metric | B3: Value | C3: Notes
A4: Shortlets add-on | B4: =01_Assumptions!B31 | C4: Module fee
A5: Locations typical | B5: =01_Assumptions!B54
A6: Locations included | B6: =01_Assumptions!B32
A7: Billable extra locations | B7: =MAX(0,B5-B6)
A8: Location revenue | B8: =B7*01_Assumptions!B33
A9: Subscription shortlets total | B9: =B4+B8 | C9: Add-on + locations
A10: GMV monthly | B10: =01_Assumptions!B55 | C10: Gross booking value
A11: GMV via checkout | B11: =B10*01_Assumptions!B56
A12: GMV via WhatsApp | B12: =B10*01_Assumptions!B57
A13: GMV offline | B13: =B10*01_Assumptions!B58 | C13: 0% take
A14: Take revenue checkout | B14: =B11*01_Assumptions!B34
A15: Take revenue WhatsApp | B15: =B12*01_Assumptions!B35
A16: Take revenue offline | B16: =B13*01_Assumptions!B36
A17: Gross take-rate revenue | B17: =B14+B15+B16
A18: Processor cost (in-rail) | B18: =(B11+B12)*01_Assumptions!B16 | C18: Paystack % on checkout+WA GMV (simplify flat)
A19: Net take-rate | B19: =IF(01_Assumptions!B37=1,MAX(0,B17-B18),B17)
A20: Total shortlets revenue | B20: =B9+B19
A21: COGS locations | B21: =B5*01_Assumptions!B14
A22: Contribution ₦ | B22: =B20-B21
A23: Contribution margin % | B23: =IF(B20=0,0,B22/B20)
A26: Blended take-rate on total GMV | B26: =IF(B10=0,0,B17/B10) | C26: Should land ~1.5–2.5% of all GMV if mix is 35/25/40
A28: Effective platform fee on in-rail only | B28: =IF((B11+B12)=0,0,B17/(B11+B12))
A30: Decision checks
A31: If contribution margin on shortlets < 60%, raise location fee or take-rate — or cut included locations.
A32: If blended take on total GMV > 4%, operators will push bookings offline — rebalance mix incentives.

Sheet 04_Customer_LTV
A1: Customer LTV / CAC (SaaS only, then with Shortlets)
A3: Metric | B3: Starter | C3: Growth | D3: Growth+Shortlets | E3: Notes
A4: Monthly contribution | B4: ='02_Plan_Economics'!B15 | C4: ='02_Plan_Economics'!C15 | D4: ='02_Plan_Economics'!C15+'03_Shortlets'!B22 | E4: After variable COGS
A5: Monthly churn | B5: =01_Assumptions!B44 | C5: =01_Assumptions!B45 | D5: =01_Assumptions!B45 | E5: Shortlets assumed same churn as Growth
A6: Expected lifetime (months) | B6: =IF(B5=0,0,1/B5) | C6: =IF(C5=0,0,1/C5) | D6: =IF(D5=0,0,1/D5) | E6: 1/churn
A7: LTV (contribution) | B7: =B4*B6 | C7: =C4*C6 | D7: =D4*D6 | E7: Simple undiscounted
A8: Setup fee contribution | B8: =01_Assumptions!B41-01_Assumptions!B42 | C8: =01_Assumptions!B41-01_Assumptions!B42 | D8: =01_Assumptions!B41-01_Assumptions!B42 | E8: One-time
A9: LTV + setup | B9: =B7+B8 | C9: =C7+C8 | D9: =D7+D8
A10: CAC | B10: =01_Assumptions!B40 | C10: =01_Assumptions!B40 | D10: =01_Assumptions!B40 | E10: Blended
A11: LTV:CAC | B11: =IF(B10=0,0,B9/B10) | C11: =IF(C10=0,0,C9/C10) | D11: =IF(D10=0,0,D9/D10) | E11: Target ≥ 3x
A12: Months to recover CAC | B12: =IF(B4=0,0,B10/B4) | C12: =IF(C4=0,0,C10/C4) | D12: =IF(D4=0,0,D10/D4) | E12: Payback (months)
A13: Healthy? | B13: =IF(AND(B11>=3,B12<=6),"YES","REVIEW") | C13: =IF(AND(C11>=3,C12<=6),"YES","REVIEW") | D13: =IF(AND(D11>=3,D12<=6),"YES","REVIEW") | E13: LTV:CAC≥3 and payback≤6
A16: Rule of thumb
A17: If Growth LTV:CAC < 3x, raise price or cut CAC (founder-led sales) before scaling ads. Shortlets take-rate is what makes Growth+Shortlets clearly >3x.

Sheet 05_Portfolio_Mix
A1: Portfolio mix — edit customer counts (yellow)
A3: Segment | B3: Count | C3: ARPU contrib/mo | D3: Segment contrib | E3: % of logos | F3: Notes
A4: Starter | B4: 8 | C4: ='02_Plan_Economics'!B15 | D4: =B4*C4 | E4: =IF(SUM($B$4:$B$7)=0,0,B4/SUM($B$4:$B$7)) | F4: Acquisition wedge
A5: Growth (no shortlets) | B5: 12 | C5: ='02_Plan_Economics'!C15 | D5: =B5*C5 | E5: =IF(SUM($B$4:$B$7)=0,0,B5/SUM($B$4:$B$7)) | F5: Core CRM/ERP
A6: Growth + Shortlets | B6: 6 | C6: ='02_Plan_Economics'!C15+'03_Shortlets'!B22 | D6: =B6*C6 | E6: =IF(SUM($B$4:$B$7)=0,0,B6/SUM($B$4:$B$7)) | F6: Highest ARPU
A7: Enterprise | B7: 2 | C7: ='02_Plan_Economics'!D15 | D7: =B7*C7 | E7: =IF(SUM($B$4:$B$7)=0,0,B7/SUM($B$4:$B$7)) | F7: Anchor accounts
A9: Total logos | B9: =SUM(B4:B7)
A10: Total monthly contribution | B10: =SUM(D4:D7)
A11: Blended contrib / logo | B11: =IF(B9=0,0,B10/B9)
A12: Fixed platform OpEx | B12: ='01_Assumptions'!B9
A13: Portfolio profit after fixed | B13: =B10-B12
A14: Logos needed to cover fixed OpEx | B14: =IF(B11=0,0,ROUNDUP(B12/B11,0)) | C14: Break-even logo count at this mix

Sheet 06_Sensitivity
A1: Sensitivity — Growth+Shortlets monthly contribution vs take-rate × location fee
A2: Static snapshot using Assumptions defaults (recalculate mentally or duplicate sheet after changing inputs). Values below are computed from current assumption cells via formulas tied to base case.
A4: One-way: Checkout take-rate
A5: Take % | B5: Illustrative net take on 35% of ₦4.5m GMV | C5: Delta vs 3%
A6: 0.02 | B6: 31500 | C6: -15750
A7: 0.025 | B7: 39375 | C7: -7875
A8: 0.03 | B8: 47250 | C8: 0
A9: 0.035 | B9: 55125 | C9: 7875
A10: 0.04 | B10: 63000 | C10: 15750
A11: 0.05 | B11: 78750 | C11: 31500
A14: One-way: Extra location fee
A15: Fee / location | B15: Rev if 1 extra loc | C15: Rev if 3 extra loc
A16: 10000 | B16: 10000 | C16: 30000
A17: 15000 | B17: 15000 | C17: 45000
A18: 20000 | B18: 20000 | C18: 60000
A19: 25000 | B19: 25000 | C19: 75000
A20: 30000 | B20: 30000 | C20: 90000
A23: One-way: Growth list price
A24: Price | B24: Approx contrib* | C24: *Assumes ~₦15k variable COGS; edit if needed
A25: 150000 | B25: 127500
A26: 180000 | B26: 156000
A27: 200000 | B27: 175000
A28: 225000 | B28: 198750
A29: 250000 | B29: 222500
A30: 300000 | B30: 270000

Sheet 07_12Mo_Path
A1: 12-month path (edit yellow new logos / mo)
A3: New Growth logos / month | B3: 2 | C3: 2 | D3: 2 | E3: 3 | F3: 3 | G3: 3 | H3: 3 | I3: 3 | J3: 4 | K3: 4 | L3: 4 | M3: 4 | N3: INPUT
A4: New Shortlet attach rate | B4: 0.4 | C4: 0.4 | D4: 0.4 | E4: 0.4 | F4: 0.4 | G4: 0.4 | H4: 0.4 | I4: 0.4 | J4: 0.4 | K4: 0.4 | L4: 0.4 | M4: 0.4
A5: Churn (Growth) | B5: ='01_Assumptions'!B45 | C5: ='01_Assumptions'!B45 | D5: ='01_Assumptions'!B45 | E5: ='01_Assumptions'!B45 | F5: ='01_Assumptions'!B45 | G5: ='01_Assumptions'!B45 | H5: ='01_Assumptions'!B45 | I5: ='01_Assumptions'!B45 | J5: ='01_Assumptions'!B45 | K5: ='01_Assumptions'!B45 | L5: ='01_Assumptions'!B45 | M5: ='01_Assumptions'!B45
A7: Month | B7: 1 | C7: 2 | D7: 3 | E7: 4 | F7: 5 | G7: 6 | H7: 7 | I7: 8 | J7: 9 | K7: 10 | L7: 11 | M7: 12 | N7: Total / End
A8: Ending Growth logos | B8: =ROUND(5+B3-5*B5,0) | C8: =ROUND(B8+C3-B8*C5,0) | D8: =ROUND(C8+D3-C8*D5,0) | E8: =ROUND(D8+E3-D8*E5,0) | F8: =ROUND(E8+F3-E8*F5,0) | G8: =ROUND(F8+G3-F8*G5,0) | H8: =ROUND(G8+H3-G8*H5,0) | I8: =ROUND(H8+I3-H8*I5,0) | J8: =ROUND(I8+J3-I8*J5,0) | ... M8: =ROUND(L8+M3-L8*M5,0) | N8: =M8
A9: Shortlet logos (end) | B9: =ROUND(B8*B4,0) | C9: =ROUND(C8*C4,0) | D9: =ROUND(D8*D4,0) | E9: =ROUND(E8*E4,0) | F9: =ROUND(F8*F4,0) | G9: =ROUND(G8*G4,0) | H9: =ROUND(H8*H4,0) | I9: =ROUND(I8*I4,0) | ... M9: =ROUND(M8*M4,0)
A10: Growth contrib ₦ | B10: =B8*'02_Plan_Economics'!C15+(B9*'03_Shortlets'!B22) | C10: =C8*'02_Plan_Economics'!C15+(C9*'03_Shortlets'!B22) | D10: =D8*'02_Plan_Economics'!C15+(D9*'03_Shortlets'!B22) | E10: =E8*'02_Plan_Economics'!C15+(E9*'03_Shortlets'!B22) | F10: =F8*'02_Plan_Economics'!C15+(F9*'03_Shortlets'!B22) | G10: =G8*'02_Plan_Economics'!C15+(G9*'03_Shortlets'!B22) | H10: =H8*'02_Plan_Economics'!C15+(H9*'03_Shortlets'!B22) | I10: =I8*'02_Plan_Economics'!C15+(I9*'03_Shortlets'!B22) | J10: =J8*'02_Plan_Economics'!C15+(J9*'03_Shortlets'!B22) | K10: =K8*'02_Plan_Economics'!C15+(K9*'03_Shortlets'!B22) | L10: =L8*'02_Plan_Economics'!C15+(L9*'03_Shortlets'!B22) | M10: =M8*'02_Plan_Economics'!C15+(M9*'03_Shortlets'!B22) | N10: =SUM(B10:M10)
A11: Fixed OpEx | B11: ='01_Assumptions'!B9 | C11: ='01_Assumptions'!B9 | D11: ='01_Assumptions'!B9 | E11: ='01_Assumptions'!B9 | F11: ='01_Assumptions'!B9 | G11: ='01_Assumptions'!B9 | H11: ='01_Assumptions'!B9 | I11: ='01_Assumptions'!B9 | J11: ='01_Assumptions'!B9 | K11: ='01_Assumptions'!B9 | L11: ='01_Assumptions'!B9 | M11: ='01_Assumptions'!B9
A12: Net after fixed | B12: =B10-B11 | C12: =C10-C11 | D12: =D10-D11 | E12: =E10-E11 | F12: =F10-F11 | G12: =G10-G11 | H12: =H10-H11 | I12: =I10-I11 | ... M12: =M10-M11 | N12: =SUM(B12:M12)
A14: Starts from 5 Growth logos in month 0. This is a planning sketch — not accounting.

Sheet 08_Claude_Prompt
A1: Copy-paste prompt (if you want Claude to extend this model)
A3: You are a SaaS CFO advisor for Realcorp, a Nigerian multi-tenant PropTech CRM/ERP (Next.js). Plans: STARTER / GROWTH / ENTERPRISE. Modules include Sales, Finance, Marketing, Clients, HR/Payslips, Shortlets PMS, WhatsApp agent, AI document reader, Facility, Investor portal. Build / refine a unit economics model in Naira with: 1) Assumptions tab (editable): fixed OpEx, COGS per org/seat/shortlet location, Paystack fees, list prices, seat includes, shortlets add-on, per-location fee, take-rates (checkout 3%, WhatsApp 4%, offline 0%), CAC, setup fee, churn by plan, collection rate, typical GMV and channel mix. 2) Plan economics: monthly revenue, variable COGS, contribution ₦ and % for Starter / Growth / Enterprise. 3) Shortlets: add-on + billable locations (beyond included) + take-rate only on Realcorp checkout and WhatsApp-originated paid bookings. Show blended take on total GMV vs in-rail GMV. Net of Paystack if pass-through. 4) LTV/CAC: lifetime months = 1/monthly churn; LTV = monthly contribution × lifetime + setup contribution; LTV:CAC and payback months. Flag healthy if LTV:CAC ≥ 3 and payback ≤ 6. 5) Portfolio mix: counts of Starter / Growth / Growth+Shortlets / Enterprise → total contribution vs fixed OpEx and break-even logos. 6) Sensitivity tables for take-rate, location fee, Growth price. 7) 12-month logo ramp sketch. Defaults to use unless I override: - Starter ₦90k (5 seats), Growth ₦225k (15), Enterprise ₦500k (40) - Extra seats ₦8k / ₦7k / ₦5k - Shortlets add-on ₦70k incl 2 locations; extra location ₦20k - Typical shortlet GMV ₦4.5m/mo; mix 35% checkout / 25% WhatsApp / 40% offline - CAC ₦180k; setup fee ₦250k (delivery cost ₦80k) - Churn 5% / 3% / 1.5% monthly - Target contribution margin 75% Output: Excel-ready tables OR CSV sheets I can paste. Explain which levers move contribution most for Nigerian developer/shortlet operators. Do not invent US-dollar SaaS pricing.
